Within_PC_test/Actual_Orders_lists_B.csv
Date(YYYY-MM-DD),Action(buy/sell),Number of units,Ticker,Price
2025-12-18,Sell,7000,RTX,
2026-01-15,buy,100,AAPL,260.6499938964844
2026-01-15,buy,100,AAPL,260.6499938964844
2026-01-15,buy,100,AAPL,258.0
2026-01-15,sell,100,AAPL,260.8
2026-01-15,sell,100,AAPL,260.6499938964844
2026-01-15,sell,100,AAPL,260.6499938964844
