Within_PC_test/Limit_order_B.csv
Date(YYYY-MM-DD),Action(buy/sell),TriggerPrice,Number of units,Ticker,Status
2025-06-23,Sell,200,7000,RTX,Active
2025-06-23,Sell,170,7000,RTX,Complete
2025-06-23,Sell,260,7000,AAPL,Complete
2025-06-23,Sell,260,7000,AAPL,Complete
2025-12-22,Sell,1000,100,AAPL,Active
2025-12-22,Sell,240,100,AAPL,Complete
2025-01-10,Sell,10,100,AAPL,Complete
2025-01-10,Sell,1000,100,AAPL,Active
2025-01-10,buy,1000,100,AAPL,Complete
2025-01-10,buy,10,100,AAPL,Active
